<?xml version="1.0"?>
<robot xmlns:xacro="http://www.ros.org/wiki/xacro" name="rob_teleeop">
    <xacro:arg name="gazebo" default="false"/>

    <xacro:include filename="$(find rob_teleeop)/ff.urdf.xacro" />
    <xacro:property name="M_PI" value="3.14159"/>

    <link name="base_link">
        <visual>
        <origin xyz="0 0 0" rpy="0 0 0"/>
            <geometry>
                <mesh filename="file:///$(find rob_teleeop)/robot_nano_hand_base.stl" scale="1 1 1"/>
            </geometry>
        </visual>

        <collision>
            <origin xyz="0 0 0" rpy="0 0 0"/>
            <geometry>
                <mesh filename="file:///$(find rob_teleeop)/robot_nano_hand_base.stl" scale="1 1 1"/>
            </geometry>
        </collision>
        <!-- Add definition for all missing variable -->
    </link>
    <!-- Palm link -->
    <link name="palm_link">
        <visual>
            <origin xyz="0 0 0" rpy="0 0 0"/>
            <geometry>
                <mesh filename="file:///$(find rob_teleeop)/robot_nano_hand_palm.stl" scale="1 1 1"/>
            </geometry>
        </visual>

        <collision>
            <origin xyz="0 0 0" rpy="0 0 0"/>
            <geometry>
                <mesh filename="file:///$(find rob_teleeop)/robot_nano_hand_palm.stl" scale="1 1 1"/>
            </geometry>
        </collision>
    </link>

    <!-- Palm joint -->
    <joint name="handle_joint" type="revolute">
        <axis xyz="1 0 0" />
        <limit effort="0" velocity="0" lower="0" upper="50" />
        <origin xyz="0 0 0.10" rpy="0 0 0" />
        <parent link="base_link" />
        <child link="palm_link" />
    </joint>

    <!-- Macro finger -->
 <xacro:ff base_ref="palm_link" nb="1" r1="0.134884 0.077146 0.149703" p1="0.014588 -0.034298 0.105371" p2="0 0 0.0026" p3="0.00357 0.000126 0.040844" p4="0.006306 0.000139 0.029247"/>
 <xacro:ff base_ref="palm_link" nb="2" r1="0.062643 -0.000111 0.073654" p1="0.007772 -0.013612 0.117984" p2="0 0 0.0026" p3="-0.003183 0 0.045388" p4="-0.002027 0 0.032436"/>
</robot>