<?xml version="1.0"?>
<robot xmlns:xacro="http://www.ros.org/wiki/xacro" name="rob_teleeop">
    <xacro:arg name="gazebo" default="false"/>

    <xacro:include filename="$(find rob_teleeop)/finger.urdf.xacro" />
    <xacro:property name="M_PI" value="3.14159"/>

    <link name="base_link">
        <visual>
            <origin xyz="0 0 0" rpy="0 0 0"/>
            <geometry>
                <mesh filename="file:///$(find rob_teleeop)/robot_nano_hand_base.stl" scale="1 1 1"/>
            </geometry>
        </visual>

        <collision>
            <origin xyz="0 0 0" rpy="0 0 0"/>
            <geometry>
                <mesh filename="file:///$(find rob_teleeop)/robot_nano_hand_base.stl" scale="1 1 1"/>
            </geometry>
        </collision>
        <!-- Add definition for all missing variable -->
    </link>
    <!-- Palm link -->
    <link name="palm_link">
        <visual>
            <origin xyz="0 0 0" rpy="0 0 0"/>
            <geometry>
                <mesh filename="file:///$(find rob_teleeop)/robot_nano_hand_palm.stl" scale="1 1 1"/>
            </geometry>
        </visual>

        <collision>
            <origin xyz="0 0 0.123" rpy="0 0 0"/>
            <geometry>
                <mesh filename="file:///$(find rob_teleeop)/robot_nano_hand_palm.stl" scale="1 1 1"/>
            </geometry>
        </collision>
    </link>

    <!-- Palm joint -->
    <joint name="my_joint" type="continuous">
        <origin xyz="0 0 0.10" rpy="0 0 0" />
        <parent link="base_link" />
        <child link="palm_link" />
        <limit effort="100" velocity="0" lower="0" upper="12" />
    </joint>

    <!-- Macro finger -->
    <xacro:finger parent="palm_link" prefix="finger1" link="1" joint_type="continuous" xyz="0.015141 -0.034337 0.105315" rpy="-241.826 96.5038 0.105315"/>

    <xacro:finger parent="finger1_link" prefix="finger2" link="2" joint_type="continuous" xyz="-0.002487 0 0" rpy="9.00686 -0.124082 89.8118"/>

    <xacro:finger parent="finger2_link" prefix="finger3" link="3" joint_type="continuous" xyz="-0.040844 0.000126 0.00357" rpy="8.94359 0.091051 89.9831"/>

    <xacro:finger parent="finger3_link" prefix="finger4" link="4" joint_type="continuous" xyz="-0.029121 0.000013 0.002736" rpy="11.2847 -0.04374 89.947"/>
</robot>